<?xml version="1.0"?>
<robot xmlns:xacro="http://www.ros.org/wiki/xacro">
    <link name="gripper_base">
        <visual>
            <origin xyz="0 0 0" rpy="0 -0 0" />
            <geometry>
                <mesh filename="file://$(find xarm_description)/meshes/stls/gripper_base.stl" />
            </geometry>
            <material name="gripper_base_material">
                <color
                    rgba="0.90196078431372550543 0.90196078431372550543 0.90196078431372550543 1.0" />
            </material>
        </visual>
        <collision>
            <origin xyz="0 0 0" rpy="0 -0 0" />
            <geometry>
                <mesh filename="file://$(find xarm_description)/meshes/stls/gripper_base.stl" />
            </geometry>
        </collision>
        <inertial>
            <origin xyz="0.026027605368087160242 1.3461538473115585546e-19 -0.010448180152627458903"
                rpy="0 0 0" />
            <mass value="0.050000000000000016653" />
            <inertia ixx="1.6770018641630726693e-05" ixy="0" ixz="5.0898449727136606593e-07"
                iyy="7.9670792501893985074e-06" iyz="0" izz="1.6977316405971644377e-05" />
        </inertial>
    </link>

    <link name="finger_r">
        <visual>
            <origin xyz="-0.028999999999999987593 0.0045000000000000005274 0.03500000000000001027"
                rpy="1.570796326794896558 4.3368086899420211873e-16 0" />
            <geometry>
                <mesh filename="file://$(find xarm_description)/meshes/stls/finger_r.stl" />
            </geometry>
            <material name="finger_r_material">
                <color rgba="0.4000000000000000222 0.4000000000000000222 0.4000000000000000222 1.0" />
            </material>
        </visual>
        <collision>
            <origin xyz="-0.028999999999999987593 0.0045000000000000005274 0.03500000000000001027"
                rpy="1.570796326794896558 4.3368086899420211873e-16 0" />
            <geometry>
                <mesh filename="file://$(find xarm_description)/meshes/stls/finger_r.stl" />
            </geometry>
        </collision>
        <inertial>
            <origin
                xyz="0.039891304347826103682 -0.00032608695652173915608 0.0039999999999999844708"
                rpy="0 0 0" />
            <mass value="0.0074519999999999985557" />
            <inertia ixx="6.1307608695652002668e-08" ixy="-6.6560869565217393766e-08"
                ixz="1.1197067390126327858e-21" iyy="2.6613559565217387824e-06"
                iyz="2.886617575405322195e-23" izz="2.6431755652173915757e-06" />
        </inertial>
    </link>

    <joint name="finger_r_joint" type="prismatic">
        <origin xyz="0.029000000000000001471 -0.034999999999999996392 0.0045000000000000005274"
            rpy="-1.570796326794896558 -0 0" />
        <parent link="gripper_base" />
        <child link="finger_r" />
        <axis xyz="0 0 1" />
        <limit effort="1" velocity="20" lower="0" upper="0.026" />
        <joint_properties friction="0.0" />
    </joint>

    <link name="finger_l">
        <visual>
            <origin xyz="-0.028999999999999987593 -0.0045000000000000005274 0.03500000000000001027"
                rpy="-1.570796326794896558 4.3368086899420211873e-16 0" />
            <geometry>
                <mesh filename="file://$(find xarm_description)/meshes/stls/finger_l.stl" />
            </geometry>
            <material name="finger_l_material">
                <color rgba="0.4000000000000000222 0.4000000000000000222 0.4000000000000000222 1.0" />
            </material>
        </visual>
        <collision>
            <origin xyz="-0.028999999999999987593 -0.0045000000000000005274 0.03500000000000001027"
                rpy="-1.570796326794896558 4.3368086899420211873e-16 0" />
            <geometry>
                <mesh filename="file://$(find xarm_description)/meshes/stls/finger_l.stl" />
            </geometry>
        </collision>
        <inertial>
            <origin xyz="0.039891304347826103682 0.00032608695652173915608 0.0039999999999999844708"
                rpy="0 0 0" />
            <mass value="0.0074519999999999985557" />
            <inertia ixx="6.1307608695652002668e-08" ixy="6.6560869565217393766e-08"
                ixz="1.1197067390126327858e-21" iyy="2.6613559565217387824e-06"
                iyz="-2.886617575405322195e-23" izz="2.6431755652173915757e-06" />
        </inertial>
    </link>

    <joint name="finger_l_joint" type="prismatic">
        <origin xyz="0.029000000000000001471 0.03500000000000001027 0.0045000000000000005274"
            rpy="1.570796326794896558 -0 0" />
        <parent link="gripper_base" />
        <child link="finger_l" />
        <axis xyz="0 0 1" />
        <limit effort="1" velocity="20" lower="0" upper="0.026" />
        <joint_properties friction="0.0" />
    </joint>
</robot>